<?xml version="1.0"?>
<robot name="bot">
    <!-- link base_footprint -->
    <link name="base_footprint">
    </link>
    <!-- joint base_link_joint -->
    <joint name="base_link_joint" type="fixed">
        <parent link="base_footprint"/>
        <child link="base_link"/>
        <origin xyz="0 0 0.085" rpy="0 0 0"/>
        <axis xyz="0 0 0"/>
    </joint>
    <!-- link base_link -->
    <link name="base_link">
        <visual>
            <geometry>
                <!-- <mesh filename="package://pkg_name/meshes/file_name"/> -->
                <!-- <box size="0.31343 0.5235 0.547" /> -->
                <box size="0.1 0.1 0.1" />
            </geometry>
            <material name="LightGrey">
                <color rgba="0.7 0.7 0.7 1.0"/>
            </material>
        </visual>
        <collision>
            <geometry>
                <!-- <mesh filename="package://pkg_name/meshes/file_name"/> -->
                <!-- <box size="0.31343 0.5235 0.547" /> -->
                <box size="0.1 0.1 0.1" />
            </geometry>
        </collision>
        <inertial>
            <mass value="0.0"/>
            <origin xyz="0.0 0.0 0.0" rpy="0.0 0.0 0.0"/>
            <inertia ixx="0.0" ixy="0.0" ixz="0.0" iyy="0.0" iyz="0.0" izz="0.0"/>
        </inertial>
    </link>
    <!-- joint whell_right_joint -->
    <joint name="wheel_right_joint" type="continuous">
        <parent link="base_link"/>
        <child link="wheel_right_link"/>
        <origin xyz="0 -0.24425 0" rpy="1.570796327 0 0"/>
        <axis xyz="0 0 1"/>
    </joint>
    <!-- link wheel_right_link -->
    <link name="wheel_right_link">
        <visual>
            <geometry>
                <!-- <mesh filename="package://pkg_name/meshes/file_name"/> -->
                <cylinder radius="0.085" length="0.035"/>
            </geometry>
            <material name="LightGrey">
                <color rgba="0.7 0.7 0.7 1.0"/>
            </material>
        </visual>
        <collision>
            <geometry>
                <!-- <mesh filename="package://pkg_name/meshes/file_name"/> -->
                <cylinder radius="0.085" length="0.035"/>
            </geometry>
        </collision>
        <inertial>
            <mass value="0.0"/>
            <origin xyz="0.0 0.0 0.0" rpy="0.0 0.0 0.0"/>
            <inertia ixx="0.0" ixy="0.0" ixz="0.0" iyy="0.0" iyz="0.0" izz="0.0"/>
        </inertial>
    </link>
    <!-- joint wheel_left_joint -->
    <joint name="wheel_left_joint" type="continuous">
        <parent link="base_link"/>
        <child link="wheel_left_link"/>
        <origin xyz="0 0.24425 0" rpy="1.570796327 0 0"/>
        <axis xyz="0 0 1"/>
    </joint>
    <!-- link wheel_left_link -->
    <link name="wheel_left_link">
        <visual>
            <geometry>
                <!-- <mesh filename="package://pkg_name/meshes/file_name"/> -->
                <cylinder radius="0.085" length="0.035"/>
            </geometry>
            <material name="LightGrey">
                <color rgba="0.7 0.7 0.7 1.0"/>
            </material>
        </visual>
        <collision>
            <geometry>
                <!-- <mesh filename="package://pkg_name/meshes/file_name"/> -->
                <cylinder radius="0.085" length="0.035"/>
            </geometry>
        </collision>
        <inertial>
            <mass value="0.0"/>
            <origin xyz="0.0 0.0 0.0" rpy="0.0 0.0 0.0"/>
            <inertia ixx="0.0" ixy="0.0" ixz="0.0" iyy="0.0" iyz="0.0" izz="0.0"/>
        </inertial>
    </link>
    <!-- joint lidar_2d_joint -->
    <joint name="lidar_2d_joint" type="fixed">
        <parent link="base_link"/>
        <child link="lidar_2d_link"/>
        <origin xyz="0.21415 0 0.2544" rpy="0 0 0"/>
        <axis xyz="0 0 0"/>
    </joint>
    <!-- link lidar_2d_link -->
    <link name="lidar_2d_link">
        <visual>
            <geometry>
                <!-- <mesh filename="package://pkg_name/meshes/file_name"/> -->
                <cylinder radius="0.05" length="0.05"/>
            </geometry>
            <material name="LightGrey">
                <color rgba="0.7 0.7 0.7 1.0"/>
            </material>
        </visual>
        <collision>
            <geometry>
                <!-- <mesh filename="package://pkg_name/meshes/file_name"/> -->
                <cylinder radius="0.05" length="0.05"/>
            </geometry>
        </collision>
        <inertial>
            <mass value="0.0"/>
            <origin xyz="0.0 0.0 0.0" rpy="0.0 0.0 0.0"/>
            <inertia ixx="0.0" ixy="0.0" ixz="0.0" iyy="0.0" iyz="0.0" izz="0.0"/>
        </inertial>
    </link>
    <!-- joint imu_joint -->
    <joint name="imu_joint" type="fixed">
        <parent link="base_link"/>
        <child link="imu_link"/>
        <origin xyz="-0.0627 0.03949 0.1868" rpy="0 0 0"/>
        <axis xyz="0 0 0"/>
    </joint>
    <!-- link imu_link -->
    <link name="imu_link">
        <visual>
            <geometry>
                <!-- <mesh filename="package://pkg_name/meshes/file_name"/> -->
                <box size="0.05 0.05 0.05" />
            </geometry>
            <material name="LightGrey">
                <color rgba="0.7 0.7 0.7 1.0"/>
            </material>
        </visual>
        <collision>
            <geometry>
                <!-- <mesh filename="package://pkg_name/meshes/file_name"/> -->
                <box size="0.05 0.05 0.05" />
            </geometry>
        </collision>
        <inertial>
            <mass value="0.0"/>
            <origin xyz="0.0 0.0 0.0" rpy="0.0 0.0 0.0"/>
            <inertia ixx="0.0" ixy="0.0" ixz="0.0" iyy="0.0" iyz="0.0" izz="0.0"/>
        </inertial>
    </link>
    <!-- joint camera_high_joint -->
    <joint name="camera_high_joint" type="fixed">
        <parent link="base_link"/>
        <child link="camera_high_link"/>
        <origin xyz="0.2 0 0.1" rpy="0 0 0"/>
        <axis xyz="0 0 0"/>
    </joint>
    <!-- link camera_high_link -->
    <link name="camera_high_link">
        <visual>
            <geometry>
                <!-- <mesh filename="package://pkg_name/meshes/file_name"/> -->
                <box size="0.02 0.08 0.05" />
            </geometry>
            <material name="LightGrey">
                <color rgba="0.7 0.7 0.7 1.0"/>
            </material>
        </visual>
        <collision>
            <geometry>
                <!-- <mesh filename="package://pkg_name/meshes/file_name"/> -->
                <box size="0.02 0.08 0.05" />
            </geometry>
        </collision>
        <inertial>
            <mass value="0.0"/>
            <origin xyz="0.0 0.0 0.0" rpy="0.0 0.0 0.0"/>
            <inertia ixx="0.0" ixy="0.0" ixz="0.0" iyy="0.0" iyz="0.0" izz="0.0"/>
        </inertial>
    </link>
    <!-- joint camera_low_joint -->
    <joint name="camera_low_joint" type="fixed">
        <parent link="base_link"/>
        <child link="camera_low_link"/>
        <origin xyz="0.2 0 0" rpy="0 0 0"/>
        <axis xyz="0 0 0"/>
    </joint>
    <!-- link camera_low_link -->
    <link name="camera_low_link">
        <visual>
            <geometry>
                <!-- <mesh filename="package://pkg_name/meshes/file_name"/> -->
                <box size="0.02 0.08 0.05" />
            </geometry>
            <material name="LightGrey">
                <color rgba="0.7 0.7 0.7 1.0"/>
            </material>
        </visual>
        <collision>
            <geometry>
                <!-- <mesh filename="package://pkg_name/meshes/file_name"/> -->
                <box size="0.02 0.08 0.05" />
            </geometry>
        </collision>
        <inertial>
            <mass value="0.0"/>
            <origin xyz="0.0 0.0 0.0" rpy="0.0 0.0 0.0"/>
            <inertia ixx="0.0" ixy="0.0" ixz="0.0" iyy="0.0" iyz="0.0" izz="0.0"/>
        </inertial>
    </link>
</robot>
